<?xml version="1.0"?>
<robot xmlns:xacro="http://www.ros.org/wiki/xacro" name="myAGV">

  <link name="base_footprint"/>

  <joint name="base_footprint_joint" type="fixed">
    <origin xyz="0.0 0.0 0.06" rpy="0 0 0"/>
    <parent link="base_footprint"/>
    <child link="base_link"/>
  </joint>

  <link name="base_link">
    <visual>
      <geometry><box size="0.34 0.24 0.10"/></geometry>
      <origin xyz="0.0 0.0 0.0" rpy="0.0 0.0 0.0"/>
      <material name="yellow"><color rgba="0.7 0.7 0.0 1.0"/></material>
    </visual>
    <collision>
      <geometry><box size="0.34 0.24 0.10"/></geometry>
      <origin xyz="0.0 0.0 0.0" rpy="0.0 0.0 0.0"/>
    </collision>
    <inertial>
      <mass value="5.0"/>
      <origin xyz="0.0 0.0 0.0" rpy="0 0 0"/>
      <inertia ixx="0.0408" ixy="0.0" ixz="0.0" iyy="0.0642" iyz="0.0" izz="0.0897"/>
    </inertial>
  </link>

  <joint name="lidar_joint" type="fixed">
    <origin xyz="0.0 0.0 0.08" rpy="0 0 0"/>
    <parent link="base_link"/>
    <child link="laser_frame"/>
  </joint>
  <link name="laser_frame">
    <visual>
      <geometry><cylinder radius="0.04" length="0.04"/></geometry>
      <material name="black"><color rgba="0.1 0.1 0.1 1.0"/></material>
    </visual>
    <collision>
      <geometry><cylinder radius="0.04" length="0.04"/></geometry>
    </collision>
    <inertial>
      <mass value="0.1"/>
      <inertia ixx="0.0001" ixy="0" ixz="0" iyy="0.0001" iyz="0" izz="0.0001"/>
    </inertial>
  </link>

  <joint name="front_left_wheel_joint" type="continuous">
    <origin xyz="0.10 0.14 -0.045" rpy="-1.5708 0 0"/>
    <parent link="base_link"/>
    <child link="front_left_wheel"/>
    <axis xyz="0 0 1"/>
    <dynamics damping="0.1" friction="0.1"/>
  </joint>
  <link name="front_left_wheel">
    <visual><geometry><cylinder radius="0.055" length="0.04"/></geometry></visual>
    <collision><geometry><cylinder radius="0.055" length="0.04"/></geometry></collision>
    <inertial>
      <mass value="0.3"/>
      <inertia ixx="0.0002" ixy="0" ixz="0" iyy="0.0002" iyz="0" izz="0.0004"/>
    </inertial>
  </link>

  <joint name="front_right_wheel_joint" type="continuous">
    <origin xyz="0.10 -0.14 -0.045" rpy="-1.5708 0 0"/>
    <parent link="base_link"/>
    <child link="front_right_wheel"/>
    <axis xyz="0 0 1"/>
    <dynamics damping="0.1" friction="0.1"/>
  </joint>
  <link name="front_right_wheel">
    <visual><geometry><cylinder radius="0.055" length="0.04"/></geometry></visual>
    <collision><geometry><cylinder radius="0.055" length="0.04"/></geometry></collision>
    <inertial>
      <mass value="0.3"/>
      <inertia ixx="0.0002" ixy="0" ixz="0" iyy="0.0002" iyz="0" izz="0.0004"/>
    </inertial>
  </link>

  <joint name="rear_left_wheel_joint" type="continuous">
    <origin xyz="-0.10 0.14 -0.045" rpy="-1.5708 0 0"/>
    <parent link="base_link"/>
    <child link="rear_left_wheel"/>
    <axis xyz="0 0 1"/>
    <dynamics damping="0.1" friction="0.1"/>
  </joint>
  <link name="rear_left_wheel">
    <visual><geometry><cylinder radius="0.055" length="0.04"/></geometry></visual>
    <collision><geometry><cylinder radius="0.055" length="0.04"/></geometry></collision>
    <inertial>
      <mass value="0.3"/>
      <inertia ixx="0.0002" ixy="0" ixz="0" iyy="0.0002" iyz="0" izz="0.0004"/>
    </inertial>
  </link>

  <joint name="rear_right_wheel_joint" type="continuous">
    <origin xyz="-0.10 -0.14 -0.045" rpy="-1.5708 0 0"/>
    <parent link="base_link"/>
    <child link="rear_right_wheel"/>
    <axis xyz="0 0 1"/>
    <dynamics damping="0.1" friction="0.1"/>
  </joint>
  <link name="rear_right_wheel">
    <visual><geometry><cylinder radius="0.055" length="0.04"/></geometry></visual>
    <collision><geometry><cylinder radius="0.055" length="0.04"/></geometry></collision>
    <inertial>
      <mass value="0.3"/>
      <inertia ixx="0.0002" ixy="0" ixz="0" iyy="0.0002" iyz="0" izz="0.0004"/>
    </inertial>
  </link>

  <gazebo>
    <plugin name="gazebo_ros_diff_drive" filename="libgazebo_ros_diff_drive.so">
      <ros>
        <remapping>cmd_vel:=cmd_vel</remapping>
        <remapping>odom:=odom</remapping>
      </ros>
      <left_joint>front_left_wheel_joint</left_joint>
      <right_joint>front_right_wheel_joint</right_joint>
      <wheel_separation>0.28</wheel_separation>
      <wheel_diameter>0.11</wheel_diameter>
      <max_wheel_torque>50</max_wheel_torque>
      <max_wheel_acceleration>10.0</max_wheel_acceleration>
      <publish_odom>true</publish_odom>
      <publish_odom_tf>true</publish_odom_tf>
      <publish_wheel_tf>false</publish_wheel_tf>
      <odometry_frame>odom</odometry_frame>
      <robot_base_frame>base_footprint</robot_base_frame>
    </plugin>
  </gazebo>

  <gazebo reference="front_left_wheel">
    <material>Gazebo/DarkGrey</material>
    <mu1>1.5</mu1><mu2>1.5</mu2>
    <kp>100000.0</kp><kd>10.0</kd>
    <minDepth>0.001</minDepth><maxVel>100</maxVel>
  </gazebo>
  <gazebo reference="front_right_wheel">
    <material>Gazebo/DarkGrey</material>
    <mu1>1.5</mu1><mu2>1.5</mu2>
    <kp>100000.0</kp><kd>10.0</kd>
    <minDepth>0.001</minDepth><maxVel>100</maxVel>
  </gazebo>
  <gazebo reference="rear_left_wheel">
    <material>Gazebo/DarkGrey</material>
    <mu1>0.05</mu1><mu2>0.05</mu2>
    <kp>100000.0</kp><kd>10.0</kd>
    <minDepth>0.001</minDepth><maxVel>100</maxVel>
  </gazebo>
  <gazebo reference="rear_right_wheel">
    <material>Gazebo/DarkGrey</material>
    <mu1>0.05</mu1><mu2>0.05</mu2>
    <kp>100000.0</kp><kd>10.0</kd>
    <minDepth>0.001</minDepth><maxVel>100</maxVel>
  </gazebo>

  <gazebo reference="laser_frame">
    <material>Gazebo/Black</material>
    <sensor type="ray" name="lidar_sensor">
      <pose>0 0 0 0 0 0</pose>
      <visualize>false</visualize>
      <update_rate>10</update_rate>
      <ray>
        <scan>
          <horizontal>
            <samples>360</samples>
            <resolution>1</resolution>
            <min_angle>-3.14159</min_angle>
            <max_angle>3.14159</max_angle>
          </horizontal>
        </scan>
        <range>
          <min>0.12</min>
          <max>12.0</max>
          <resolution>0.01</resolution>
        </range>
        <noise>
          <type>gaussian</type>
          <mean>0.0</mean>
          <stddev>0.01</stddev>
        </noise>
      </ray>
      <plugin name="gazebo_ros_lidar" filename="libgazebo_ros_ray_sensor.so">
        <ros>
          <remapping>~/out:=scan</remapping>
        </ros>
        <output_type>sensor_msgs/LaserScan</output_type>
        <frame_name>laser_frame</frame_name>
      </plugin>
    </sensor>
  </gazebo>

</robot>
